<mujoco model="dual arm v5">
  <compiler angle="radian" meshdir="/root/franka-panda-project/vendor/mujoco_menagerie/franka_emika_panda/assets" autolimits="true"/>
  <option timestep="0.002" integrator="implicitfast">
    <flag eulerdamp="disable"/>
  </option>
  <visual>
    <global offwidth="1920" offheight="1080"/>
    <headlight diffuse="0.5 0.5 0.5" ambient="0.3 0.3 0.3"/>
  </visual>
  <default>
    <default class="panda">
      <material specular="0.5" shininess="0.25"/>
      <joint armature="0.1" damping="1" axis="0 0 1" range="-2.8973 2.8973"/>
      <general dyntype="none" biastype="affine" ctrlrange="-2.8973 2.8973" forcerange="-87 87"/>
      <default class="finger">
        <joint axis="0 1 0" type="slide" range="0 0.04"/>
      </default>
      <default class="visual">
        <geom type="mesh" contype="0" conaffinity="0" group="2"/>
      </default>
      <default class="collision">
        <geom type="mesh" group="3"/>
      </default>
    </default>
  </default>
  <asset>
    <texture type="skybox" builtin="gradient" rgb1="0.12 0.2 0.35" rgb2="0.02 0.02 0.06" width="512" height="3072"/>
    <texture type="2d" name="grid" builtin="checker" rgb1=".55 .55 .55" rgb2=".35 .35 .35" width="512" height="512"/>
    <material name="grid_mat" texture="grid" texrepeat="12 12" reflectance="0.12"/>
    <material class="panda" name="white" rgba="0.95 0.95 0.95 1"/>
    <material class="panda" name="off_white" rgba="0.85 0.87 0.88 1"/>
    <material class="panda" name="black" rgba="0.15 0.15 0.15 1"/>
    <material class="panda" name="green" rgba="0 0.8 0 1"/>
    <material class="panda" name="light_blue" rgba="0.04 0.5 0.75 1"/>
    <!-- 太空舱模块 - 更大更醒目 -->
    <material name="mod_blue" rgba="0.1 0.5 1.0 1" specular="0.6" shininess="0.5"/>
    <material name="mod_red" rgba="1.0 0.25 0.15 1" specular="0.6" shininess="0.5"/>
    <material name="mod_green" rgba="0.15 0.9 0.35 1" specular="0.6" shininess="0.5"/>
    <material name="table_mat" rgba="0.6 0.42 0.25 1" specular="0.5" shininess="0.3" reflectance="0.1"/>
    <mesh name="link0_c" file="link0.stl"/><mesh name="link1_c" file="link1.stl"/>
    <mesh name="link2_c" file="link2.stl"/><mesh name="link3_c" file="link3.stl"/>
    <mesh name="link4_c" file="link4.stl"/>
    <mesh name="link5_c0" file="link5_collision_0.obj"/>
    <mesh name="link5_c1" file="link5_collision_1.obj"/>
    <mesh name="link5_c2" file="link5_collision_2.obj"/>
    <mesh name="link6_c" file="link6.stl"/><mesh name="link7_c" file="link7.stl"/>
    <mesh name="hand_c" file="hand.stl"/>
    <mesh file="link0_0.obj"/><mesh file="link0_1.obj"/><mesh file="link0_2.obj"/>
    <mesh file="link0_3.obj"/><mesh file="link0_4.obj"/><mesh file="link0_5.obj"/>
    <mesh file="link0_7.obj"/><mesh file="link0_8.obj"/><mesh file="link0_9.obj"/>
    <mesh file="link0_10.obj"/><mesh file="link0_11.obj"/>
    <mesh file="link1.obj"/><mesh file="link2.obj"/>
    <mesh file="link3_0.obj"/><mesh file="link3_1.obj"/><mesh file="link3_2.obj"/><mesh file="link3_3.obj"/>
    <mesh file="link4_0.obj"/><mesh file="link4_1.obj"/><mesh file="link4_2.obj"/><mesh file="link4_3.obj"/>
    <mesh file="link5_0.obj"/><mesh file="link5_1.obj"/><mesh file="link5_2.obj"/>
    <mesh file="link6_0.obj"/><mesh file="link6_1.obj"/><mesh file="link6_2.obj"/>
    <mesh file="link6_3.obj"/><mesh file="link6_4.obj"/><mesh file="link6_5.obj"/>
    <mesh file="link6_6.obj"/><mesh file="link6_7.obj"/><mesh file="link6_8.obj"/>
    <mesh file="link6_9.obj"/><mesh file="link6_10.obj"/><mesh file="link6_11.obj"/>
    <mesh file="link6_12.obj"/><mesh file="link6_13.obj"/><mesh file="link6_14.obj"/>
    <mesh file="link6_15.obj"/><mesh file="link6_16.obj"/>
    <mesh file="link7_0.obj"/><mesh file="link7_1.obj"/><mesh file="link7_2.obj"/>
    <mesh file="link7_3.obj"/><mesh file="link7_4.obj"/><mesh file="link7_5.obj"/>
    <mesh file="link7_6.obj"/><mesh file="link7_7.obj"/>
    <mesh file="hand_0.obj"/><mesh file="hand_1.obj"/><mesh file="hand_2.obj"/>
    <mesh file="hand_3.obj"/><mesh file="hand_4.obj"/>
    <mesh file="finger_0.obj"/><mesh file="finger_1.obj"/>
  </asset>

  <worldbody>
    <light pos="0.5 0.8 3" dir="-0.2 -0.3 -1" diffuse=".8 .8 .8" specular=".3 .3 .3"/>
    <light pos="-0.8 0.5 2" dir="0.3 -0.2 -1" diffuse=".4 .4 .4"/>
    <light pos="0 -1.5 2" dir="0 0.8 -1" diffuse=".3 .3 .3"/>
    <geom name="floor" size="4 4 0.1" type="plane" material="grid_mat"/>
    <geom name="table_top" type="box" pos="0 0 0.65" size="0.35 0.3 0.02" 
          material="table_mat" contype="1" conaffinity="1"/>
    <geom name="table_leg1" type="cylinder" pos="-0.3 -0.25 0.32" size="0.025 0.33"
          material="table_mat" contype="1" conaffinity="1"/>
    <geom name="table_leg2" type="cylinder" pos="0.3 -0.25 0.32" size="0.025 0.33"
          material="table_mat" contype="1" conaffinity="1"/>
    <geom name="table_leg3" type="cylinder" pos="-0.3 0.25 0.32" size="0.025 0.33"
          material="table_mat" contype="1" conaffinity="1"/>
    <geom name="table_leg4" type="cylinder" pos="0.3 0.25 0.32" size="0.025 0.33"
          material="table_mat" contype="1" conaffinity="1"/>

    <!-- 太空舱模块 - 中间位置 z=0.7 -->
    <body name="module_a" pos="-0.18 0 0.7">
      <freejoint name="module_a_free"/>
      <geom type="box" size="0.04 0.04 0.03" material="mod_blue"/>
    </body>
    <body name="module_b" pos="0 0 0.7">
      <freejoint name="module_b_free"/>
      <geom type="box" size="0.04 0.04 0.03" material="mod_red"/>
    </body>
    <body name="module_c" pos="0.18 0 0.7">
      <freejoint name="module_c_free"/>
      <geom type="box" size="0.04 0.04 0.03" material="mod_green"/>
    </body>

    <!-- Left Arm - 距离拉开 x=-0.5 -->
    <body name="base_L" pos="-0.85 0.35 0">
      <body name="link0_L" childclass="panda">
        <inertial mass="0.629769" pos="-0.041018 -0.00014 0.049974" fullinertia="0.00315 0.00388 0.004285 8.2904e-7 0.00015 8.2299e-6"/>
        <geom mesh="link0_0" material="off_white" class="visual"/><geom mesh="link0_1" material="black" class="visual"/>
        <geom mesh="link0_2" material="off_white" class="visual"/><geom mesh="link0_3" material="black" class="visual"/>
        <geom mesh="link0_4" material="off_white" class="visual"/><geom mesh="link0_5" material="black" class="visual"/>
        <geom mesh="link0_7" material="white" class="visual"/><geom mesh="link0_8" material="white" class="visual"/>
        <geom mesh="link0_9" material="black" class="visual"/><geom mesh="link0_10" material="off_white" class="visual"/>
        <geom mesh="link0_11" material="white" class="visual"/><geom mesh="link0_c" class="collision"/>
        <body name="link1_L" pos="0 0 0.333">
          <inertial mass="4.970684" pos="0.003875 0.002081 -0.04762" fullinertia="0.70337 0.70661 0.0091170 -0.00013900 0.0067720 0.019169"/>
          <joint name="joint1_L"/>
          <geom material="white" mesh="link1" class="visual"/><geom mesh="link1_c" class="collision"/>
          <body name="link2_L" quat="1 -1 0 0">
            <inertial mass="0.646926" pos="-0.003141 -0.02872 0.003495" fullinertia="0.0079620 2.8110e-2 2.5995e-2 -3.925e-3 1.0254e-2 7.04e-4"/>
            <joint name="joint2_L" range="-1.7628 1.7628"/>
            <geom material="white" mesh="link2" class="visual"/><geom mesh="link2_c" class="collision"/>
            <body name="link3_L" pos="0 -0.316 0" quat="1 1 0 0">
              <joint name="joint3_L"/>
              <inertial mass="3.228604" pos="2.7518e-2 3.9252e-2 -6.6502e-2" fullinertia="3.7242e-2 3.6155e-2 1.083e-2 -4.761e-3 -1.1396e-2 -1.2805e-2"/>
              <geom mesh="link3_0" material="white" class="visual"/><geom mesh="link3_1" material="white" class="visual"/>
              <geom mesh="link3_2" material="white" class="visual"/><geom mesh="link3_3" material="black" class="visual"/>
              <geom mesh="link3_c" class="collision"/>
              <body name="link4_L" pos="0.0825 0 0" quat="1 1 0 0">
                <inertial mass="3.587895" pos="-5.317e-2 1.04419e-1 2.7454e-2" fullinertia="2.5853e-2 1.9552e-2 2.8323e-2 7.796e-3 -1.332e-3 8.641e-3"/>
                <joint name="joint4_L" range="-3.0718 -0.0698"/>
                <geom mesh="link4_0" material="white" class="visual"/><geom mesh="link4_1" material="white" class="visual"/>
                <geom mesh="link4_2" material="black" class="visual"/><geom mesh="link4_3" material="white" class="visual"/>
                <geom mesh="link4_c" class="collision"/>
                <body name="link5_L" pos="-0.0825 0.384 0" quat="1 -1 0 0">
                  <inertial mass="1.225946" pos="-1.1953e-2 4.1065e-2 -3.8437e-2" fullinertia="3.5549e-2 2.9474e-2 8.627e-3 -2.117e-3 -4.037e-3 2.29e-4"/>
                  <joint name="joint5_L"/>
                  <geom mesh="link5_0" material="black" class="visual"/><geom mesh="link5_1" material="black" class="visual"/>
                  <geom mesh="link5_2" material="black" class="visual"/>
                  <geom mesh="link5_c0" class="collision"/><geom mesh="link5_c1" class="collision"/><geom mesh="link5_c2" class="collision"/>
                  <body name="link6_L" pos="0 0 0.384" quat="1 1 0 0">
                    <inertial mass="1.66656" pos="-1.1953e-2 4.1065e-2 -3.8437e-2" fullinertia="3.5549e-2 2.9474e-2 8.627e-3 -2.117e-3 -4.037e-3 2.29e-4"/>
                    <joint name="joint6_L"/>
                    <geom mesh="link6_0" material="light_blue" class="visual"/><geom mesh="link6_1" material="light_blue" class="visual"/>
                    <geom mesh="link6_2" material="light_blue" class="visual"/><geom mesh="link6_3" material="light_blue" class="visual"/>
                    <geom mesh="link6_4" material="light_blue" class="visual"/><geom mesh="link6_5" material="light_blue" class="visual"/>
                    <geom mesh="link6_6" material="light_blue" class="visual"/><geom mesh="link6_7" material="light_blue" class="visual"/>
                    <geom mesh="link6_8" material="light_blue" class="visual"/><geom mesh="link6_9" material="black" class="visual"/>
                    <geom mesh="link6_10" material="black" class="visual"/><geom mesh="link6_11" material="white" class="visual"/>
                    <geom mesh="link6_12" material="green" class="visual"/><geom mesh="link6_13" material="white" class="visual"/>
                    <geom mesh="link6_14" material="black" class="visual"/><geom mesh="link6_15" material="black" class="visual"/>
                    <geom mesh="link6_16" material="white" class="visual"/><geom mesh="link6_c" class="collision"/>
                    <body name="link7_L" pos="0.088 0 0" quat="1 1 0 0">
                      <inertial mass="7.35522e-01" pos="1.0517e-2 -4.252e-3 6.1597e-2" fullinertia="1.2516e-2 1.0027e-2 4.815e-3 -4.28e-4 -1.196e-3 -7.41e-4"/>
                      <joint name="joint7_L"/>
                      <geom mesh="link7_0" material="white" class="visual"/><geom mesh="link7_1" material="black" class="visual"/>
                      <geom mesh="link7_2" material="black" class="visual"/><geom mesh="link7_3" material="black" class="visual"/>
                      <geom mesh="link7_4" material="black" class="visual"/><geom mesh="link7_5" material="black" class="visual"/>
                      <geom mesh="link7_6" material="black" class="visual"/><geom mesh="link7_7" material="white" class="visual"/>
                      <geom mesh="link7_c" class="collision"/>
                      <body name="hand_L" pos="0 0 0.107" quat="0.9238795 0 0 -0.3826834">
                        <inertial mass="0.73" pos="-0.01 0 0.03" diaginertia="0.001 0.0025 0.0017"/>
                        <geom mesh="hand_0" material="off_white" class="visual"/><geom mesh="hand_1" material="black" class="visual"/>
                        <geom mesh="hand_2" material="black" class="visual"/><geom mesh="hand_3" material="white" class="visual"/>
                        <geom mesh="hand_4" material="off_white" class="visual"/><geom mesh="hand_c" class="collision"/>
                        <body name="left_finger_L" pos="0 0 0.0584">
                          <inertial mass="0.015" pos="0 0 0" diaginertia="2.375e-6 2.375e-6 7.5e-7"/>
                          <joint name="finger_joint1_L" class="finger"/>
                          <site name="touch_site_L1" pos="0 0 0.02" size="0.01" rgba="1 0 0 0.5"/>
                          <geom mesh="finger_0" material="off_white" class="visual"/><geom mesh="finger_1" material="black" class="visual"/>
                          <geom mesh="finger_0" class="collision"/>
                        </body>
                        <body name="right_finger_L" pos="0 0 0.0584" quat="0 0 0 1">
                          <inertial mass="0.015" pos="0 0 0" diaginertia="2.375e-6 2.375e-6 7.5e-7"/>
                          <joint name="finger_joint2_L" class="finger"/>
                          <site name="touch_site_L2" pos="0 0 0.02" size="0.01" rgba="1 0 0 0.5"/>
                          <geom mesh="finger_0" material="off_white" class="visual"/><geom mesh="finger_1" material="black" class="visual"/>
                          <geom mesh="finger_0" class="collision"/>
                        </body>
                      </body>
                    </body>
                  </body>
                </body>
              </body>
            </body>
          </body>
        </body>
      </body>
    </body>

    <!-- Right Arm - x=0.5 对称 -->
    <body name="base_R" pos="0.85 -0.35 0" euler="0 0 3.14159">
      <body name="link0_R" childclass="panda">
        <inertial mass="0.629769" pos="-0.041018 -0.00014 0.049974" fullinertia="0.00315 0.00388 0.004285 8.2904e-7 0.00015 8.2299e-6"/>
        <geom mesh="link0_0" material="off_white" class="visual"/><geom mesh="link0_1" material="black" class="visual"/>
        <geom mesh="link0_2" material="off_white" class="visual"/><geom mesh="link0_3" material="black" class="visual"/>
        <geom mesh="link0_4" material="off_white" class="visual"/><geom mesh="link0_5" material="black" class="visual"/>
        <geom mesh="link0_7" material="white" class="visual"/><geom mesh="link0_8" material="white" class="visual"/>
        <geom mesh="link0_9" material="black" class="visual"/><geom mesh="link0_10" material="off_white" class="visual"/>
        <geom mesh="link0_11" material="white" class="visual"/><geom mesh="link0_c" class="collision"/>
        <body name="link1_R" pos="0 0 0.333">
          <inertial mass="4.970684" pos="0.003875 0.002081 -0.04762" fullinertia="0.70337 0.70661 0.0091170 -0.00013900 0.0067720 0.019169"/>
          <joint name="joint1_R"/>
          <geom material="white" mesh="link1" class="visual"/><geom mesh="link1_c" class="collision"/>
          <body name="link2_R" quat="1 -1 0 0">
            <inertial mass="0.646926" pos="-0.003141 -0.02872 0.003495" fullinertia="0.0079620 2.8110e-2 2.5995e-2 -3.925e-3 1.0254e-2 7.04e-4"/>
            <joint name="joint2_R" range="-1.7628 1.7628"/>
            <geom material="white" mesh="link2" class="visual"/><geom mesh="link2_c" class="collision"/>
            <body name="link3_R" pos="0 -0.316 0" quat="1 1 0 0">
              <joint name="joint3_R"/>
              <inertial mass="3.228604" pos="2.7518e-2 3.9252e-2 -6.6502e-2" fullinertia="3.7242e-2 3.6155e-2 1.083e-2 -4.761e-3 -1.1396e-2 -1.2805e-2"/>
              <geom mesh="link3_0" material="white" class="visual"/><geom mesh="link3_1" material="white" class="visual"/>
              <geom mesh="link3_2" material="white" class="visual"/><geom mesh="link3_3" material="black" class="visual"/>
              <geom mesh="link3_c" class="collision"/>
              <body name="link4_R" pos="0.0825 0 0" quat="1 1 0 0">
                <inertial mass="3.587895" pos="-5.317e-2 1.04419e-1 2.7454e-2" fullinertia="2.5853e-2 1.9552e-2 2.8323e-2 7.796e-3 -1.332e-3 8.641e-3"/>
                <joint name="joint4_R" range="-3.0718 -0.0698"/>
                <geom mesh="link4_0" material="white" class="visual"/><geom mesh="link4_1" material="white" class="visual"/>
                <geom mesh="link4_2" material="black" class="visual"/><geom mesh="link4_3" material="white" class="visual"/>
                <geom mesh="link4_c" class="collision"/>
                <body name="link5_R" pos="-0.0825 0.384 0" quat="1 -1 0 0">
                  <inertial mass="1.225946" pos="-1.1953e-2 4.1065e-2 -3.8437e-2" fullinertia="3.5549e-2 2.9474e-2 8.627e-3 -2.117e-3 -4.037e-3 2.29e-4"/>
                  <joint name="joint5_R"/>
                  <geom mesh="link5_0" material="black" class="visual"/><geom mesh="link5_1" material="black" class="visual"/>
                  <geom mesh="link5_2" material="black" class="visual"/>
                  <geom mesh="link5_c0" class="collision"/><geom mesh="link5_c1" class="collision"/><geom mesh="link5_c2" class="collision"/>
                  <body name="link6_R" pos="0 0 0.384" quat="1 1 0 0">
                    <inertial mass="1.66656" pos="-1.1953e-2 4.1065e-2 -3.8437e-2" fullinertia="3.5549e-2 2.9474e-2 8.627e-3 -2.117e-3 -4.037e-3 2.29e-4"/>
                    <joint name="joint6_R"/>
                    <geom mesh="link6_0" material="light_blue" class="visual"/><geom mesh="link6_1" material="light_blue" class="visual"/>
                    <geom mesh="link6_2" material="light_blue" class="visual"/><geom mesh="link6_3" material="light_blue" class="visual"/>
                    <geom mesh="link6_4" material="light_blue" class="visual"/><geom mesh="link6_5" material="light_blue" class="visual"/>
                    <geom mesh="link6_6" material="light_blue" class="visual"/><geom mesh="link6_7" material="light_blue" class="visual"/>
                    <geom mesh="link6_8" material="light_blue" class="visual"/><geom mesh="link6_9" material="black" class="visual"/>
                    <geom mesh="link6_10" material="black" class="visual"/><geom mesh="link6_11" material="white" class="visual"/>
                    <geom mesh="link6_12" material="green" class="visual"/><geom mesh="link6_13" material="white" class="visual"/>
                    <geom mesh="link6_14" material="black" class="visual"/><geom mesh="link6_15" material="black" class="visual"/>
                    <geom mesh="link6_16" material="white" class="visual"/><geom mesh="link6_c" class="collision"/>
                    <body name="link7_R" pos="0.088 0 0" quat="1 1 0 0">
                      <inertial mass="7.35522e-01" pos="1.0517e-2 -4.252e-3 6.1597e-2" fullinertia="1.2516e-2 1.0027e-2 4.815e-3 -4.28e-4 -1.196e-3 -7.41e-4"/>
                      <joint name="joint7_R"/>
                      <geom mesh="link7_0" material="white" class="visual"/><geom mesh="link7_1" material="black" class="visual"/>
                      <geom mesh="link7_2" material="black" class="visual"/><geom mesh="link7_3" material="black" class="visual"/>
                      <geom mesh="link7_4" material="black" class="visual"/><geom mesh="link7_5" material="black" class="visual"/>
                      <geom mesh="link7_6" material="black" class="visual"/><geom mesh="link7_7" material="white" class="visual"/>
                      <geom mesh="link7_c" class="collision"/>
                      <body name="hand_R" pos="0 0 0.107" quat="0.9238795 0 0 -0.3826834">
                        <inertial mass="0.73" pos="-0.01 0 0.03" diaginertia="0.001 0.0025 0.0017"/>
                        <geom mesh="hand_0" material="off_white" class="visual"/><geom mesh="hand_1" material="black" class="visual"/>
                        <geom mesh="hand_2" material="black" class="visual"/><geom mesh="hand_3" material="white" class="visual"/>
                        <geom mesh="hand_4" material="off_white" class="visual"/><geom mesh="hand_c" class="collision"/>
                        <body name="left_finger_R" pos="0 0 0.0584">
                          <inertial mass="0.015" pos="0 0 0" diaginertia="2.375e-6 2.375e-6 7.5e-7"/>
                          <joint name="finger_joint1_R" class="finger"/>
                          <site name="touch_site_R1" pos="0 0 0.02" size="0.01" rgba="1 0 0 0.5"/>
                          <geom mesh="finger_0" material="off_white" class="visual"/><geom mesh="finger_1" material="black" class="visual"/>
                          <geom mesh="finger_0" class="collision"/>
                        </body>
                        <body name="right_finger_R" pos="0 0 0.0584" quat="0 0 0 1">
                          <inertial mass="0.015" pos="0 0 0" diaginertia="2.375e-6 2.375e-6 7.5e-7"/>
                          <joint name="finger_joint2_R" class="finger"/>
                          <site name="touch_site_R2" pos="0 0 0.02" size="0.01" rgba="1 0 0 0.5"/>
                          <geom mesh="finger_0" material="off_white" class="visual"/><geom mesh="finger_1" material="black" class="visual"/>
                          <geom mesh="finger_0" class="collision"/>
                        </body>
                      </body>
                    </body>
                  </body>
                </body>
              </body>
            </body>
          </body>
        </body>
      </body>
    </body>

    <!-- 相机：更远更广，确保都看得到 -->
    <camera name="cam_main" pos="0 -2.0 1.3" xyaxes="1 0 0 0 0.55 0.84"/>
    <camera name="cam_top" pos="0 0 3.0" xyaxes="1 0 0 0 1 0"/>
    <camera name="cam_side" pos="0 -2.5 1.5" xyaxes="1 0 0 0 0.5 0.87"/>
    <camera name="cam_close_L" pos="-0.8 -1.2 1.0" xyaxes="0.8 0.6 0 0 0 1"/>
    <camera name="cam_close_R" pos="0.8 -1.2 1.0" xyaxes="-0.8 0.6 0 0 0 1"/>
  </worldbody>

  <tendon>
    <fixed name="split_L"><joint joint="finger_joint1_L" coef="0.5"/><joint joint="finger_joint2_L" coef="0.5"/></fixed>
    <fixed name="split_R"><joint joint="finger_joint1_R" coef="0.5"/><joint joint="finger_joint2_R" coef="0.5"/></fixed>
  </tendon>
  <equality>
    <joint joint1="finger_joint1_L" joint2="finger_joint2_L" solimp="0.95 0.99 0.001" solref="0.005 1"/>
    <joint joint1="finger_joint1_R" joint2="finger_joint2_R" solimp="0.95 0.99 0.001" solref="0.005 1"/>
  </equality>
  <actuator>
    <general class="panda" name="a1L" joint="joint1_L" gainprm="4500" biasprm="0 -4500 -450"/>
    <general class="panda" name="a2L" joint="joint2_L" gainprm="4500" biasprm="0 -4500 -450" ctrlrange="-1.7628 1.7628"/>
    <general class="panda" name="a3L" joint="joint3_L" gainprm="3500" biasprm="0 -3500 -350"/>
    <general class="panda" name="a4L" joint="joint4_L" gainprm="3500" biasprm="0 -3500 -350" ctrlrange="-3.0718 -0.0698"/>
    <general class="panda" name="a5L" joint="joint5_L" gainprm="2000" biasprm="0 -2000 -200" forcerange="-12 12"/>
    <general class="panda" name="a6L" joint="joint6_L" gainprm="2000" biasprm="0 -2000 -200" forcerange="-12 12" ctrlrange="-0.0175 3.7525"/>
    <general class="panda" name="a7L" joint="joint7_L" gainprm="2000" biasprm="0 -2000 -200" forcerange="-12 12"/>
    <general class="panda" name="a8L" tendon="split_L" forcerange="-100 100" ctrlrange="0 255" gainprm="0.01568627451 0 0" biasprm="0 -100 -10"/>
    <general class="panda" name="a1R" joint="joint1_R" gainprm="4500" biasprm="0 -4500 -450"/>
    <general class="panda" name="a2R" joint="joint2_R" gainprm="4500" biasprm="0 -4500 -450" ctrlrange="-1.7628 1.7628"/>
    <general class="panda" name="a3R" joint="joint3_R" gainprm="3500" biasprm="0 -3500 -350"/>
    <general class="panda" name="a4R" joint="joint4_R" gainprm="3500" biasprm="0 -3500 -350" ctrlrange="-3.0718 -0.0698"/>
    <general class="panda" name="a5R" joint="joint5_R" gainprm="2000" biasprm="0 -2000 -200" forcerange="-12 12"/>
    <general class="panda" name="a6R" joint="joint6_R" gainprm="2000" biasprm="0 -2000 -200" forcerange="-12 12" ctrlrange="-0.0175 3.7525"/>
    <general class="panda" name="a7R" joint="joint7_R" gainprm="2000" biasprm="0 -2000 -200" forcerange="-12 12"/>
    <general class="panda" name="a8R" tendon="split_R" forcerange="-100 100" ctrlrange="0 255" gainprm="0.01568627451 0 0" biasprm="0 -100 -10"/>
  </actuator>
  <sensor>
    <touch name="touch_L_f1" site="touch_site_L1"/>
    <touch name="touch_L_f2" site="touch_site_L2"/>
    <touch name="touch_R_f1" site="touch_site_R1"/>
    <touch name="touch_R_f2" site="touch_site_R2"/>
  </sensor>
</mujoco>
